Workbook

Sheet Start here
B2: Who's Buying PDX: the data behind the numbers
B4: This workbook lets you check every donor number on whosbuyingpdx.com yourself. It starts with the six candidates' public filings and walks, one step at a time, to each number on the site.
B5: Built Oct 20, 2026 from Oregon ORESTAR campaign-finance exports pulled Oct 17–18, 2026. Independent citizen project.
B7: What we're measuring, in one sentence
B8: For six business-backed candidates, how many of their donors have also given to Republican campaigns (since 2006) or to a short list of other Portland conservative campaigns. The same test run on the progressive councilors running against them finds none.
B10: Read these tabs in order
B11: 1. How we got each number — the step-by-step math, from donor lists to 125 and 390
B12: 2. Why the numbers changed — 128 → 125, 400 → 390, and the other corrections
B13: 3. How to check a row — look up any gift yourself in ORESTAR
B14: 4. Words we use — household, match, Likely, Portland conservative
B16: The data (every row is one record you can check):
B17: Candidates — donor counts and shares for all ten candidates
... B27: Not in: donor names, street addresses or employers. Each household gets a code instead (H001, P001). These are all public records, so anyone can look up a Transaction ID and see the original filing. We just aren't publishing a ready-made list of names.

Sheet How we got each number
B2: How we got each number
B4: Each step below uses live formulas that count rows in the data tabs, so you can click a number and see where it comes from.
B6: Step 1. Start with each candidate's donors
B7: We take every individual (not a business, PAC or union) who gave each candidate more than $100 since Jan 1, 2023. Those are the donors Oregon requires campaigns to name. Gifts of $100 or less, including most Small Donor Elections gifts, aren't itemized by name, so they aren't counted yet.
B8: Individual donors, all six business-backed candidates added together | C8: =SUM(Candidates!C5:C10) | D8: Torres 219, Novick 334, Clark 320, Zimmerman 288, Arnold 239, Brim-Edwards 489
B9: A person who gave to three of the six is on three lists here. We fix that in Step 4.
B11: Step 2. Check each donor against Republican campaigns
B12: For each donor, we look for gifts since 2006 to 25 Republican candidate, caucus and party committees (see the Committees tab). A Republican gift counts only if its own filing matches the donor by the same street address or PO box (same ZIP or city), or by the same ZIP and the same specific employer. A matching name alone never counts.
B13: Donor-and-candidate pairs with a Republican match | C13: =COUNTA('Candidate R matches'!B5:B1000) | D13: one row per donor per candidate
B14: matched directly by address, PO box or ZIP + employer | C14: =COUNTIF('Candidate R matches'!C5:C1000,"Confirmed")
B15: linked through another filing (explained row by row) | C15: =COUNTIF('Candidate R matches'!C5:C1000,"Likely") | D15: e.g. same employer at a home address on one gift and the office on the other
B17: Step 3. Then check the rest against Portland conservative campaigns
B18: Donors with no Republican match are checked against six local campaigns we call Portland conservative (Gonzalez, Vasquez, Mozyrsky, Adams, Treece, and a 2022 pro-Gonzalez PAC), using the same matching rules. Each donor counts once per candidate: Republican first, then Portland conservative.
B19: Donor-and-candidate pairs with a Portland-conservative match (and no Republican one) | C19: =COUNTA('Candidate PC matches'!A5:A1000)
B20: Total pairs (Republican + Portland conservative) | C20: =C13+C19
B21: These pairs give each candidate's share. Example: Zimmerman has 37 Republican + 104 Portland conservative = 141 of 288 donors = 49%. See the Candidates tab for all ten.
B23: Step 4. Count each household once (this is where 125 and 390 come from)
B24: The site's headline numbers count households, not donor-and-candidate pairs. A household is the donors with the same last name at the same home address or PO box. So a couple who both gave are one household, and a household that gave to four of the six candidates is counted once, not four times. One person who files from two addresses (home and office, a move, a typo) is also counted once. Relatives who only share a business address are not grouped: three brothers who give from their family company's office are three households.
B25: Pairs from Step 2 (Republican) | C25: =C13
B26: minus repeats where two people in one household are on the same candidate's list | C26: -8 | D26: 8 households have two members on the same candidate's donor list
B27: = household-and-candidate pairs | C27: =C25+C26
B28: minus repeats where one household gave to several of the six | C28: =-(C27-COUNTA('Republican households'!A5:A200)) | D28: 72 households gave to one candidate, 23 to two, 12 to three, 9 to four, 6 to five, 3 to all six
B29: Republican households | C29: =COUNTA('Republican households'!A5:A200) | D29: the 125 on the site
B31: Portland-conservative-only households (no Republican match for any of the six) | C31: =COUNTA('PC-only households'!A5:A400) | D31: 500 pairs from Step 3, grouped the same way
B32: Households that gave to Republicans or Portland conservatives | C32: =C29+C31 | D32: the site's headline number
B34: Other numbers on the site, counted from the Republican households tab:
B35: Gave to Christine Drazan | C35: =COUNTIF('Republican households'!D5:D200,"Yes")
B36: Gave to a Republican campaign in 2024–2026 | C36: =COUNTIF('Republican households'!G5:G200,">=2024")
B37: Gave to two or more of the six candidates | C37: =COUNTIF('Republican households'!C5:C200,">=2")
B38: Rest only on a hand-reviewed link (no direct address or ZIP + employer match) | C38: =COUNTIF('Republican households'!J5:J200,"Hand review")
B40: Step 5. The comparison
B41: We ran the exact same test on the donors of the three progressive councilors running against them (Morillo, Koyama Lane, Green): zero gave to Republicans or Portland conservatives. Shannon Singleton (County Chair, running against Brim-Edwards) has 2 of 172, both Portland conservative, none Republican. Their counts are on the Candidates tab; with zero matches there are no rows to list.

Sheet Why the numbers changed
B2: Why the numbers changed
B4: We posted these numbers Oct 18, then re-checked every Republican match against the original filings, one donor at a time. The corrections are dated on the site's Receipts page. Here is each change and why.
B6: Households that gave to Republicans | C6: was 128 | D6: now 125
B7: Three things moved it. • −8: Eight donors showed up at two addresses (home and office, a move, a typo) and had been counted as two households each. Each now counts once. • +6: Gifts from the same PO box now match like a street address. This added 7 households, and one donor's two PO-box entries turned out to be one person (+7 −1). • −1: We dropped one link with no filing behind it: a donor who shares a name with a Republican donor, but no record ties their addresses.
B9: Households that gave to Republicans or Portland conservatives | C9: was 400 | D9: now 390
B10: The same three fixes, applied to the Portland-conservative-only donors too: one person at two addresses counts once, and relatives who only share a business address are not grouped together. This tab and the site use households: 125 Republican + 265 Portland conservative only.
B12: Gave to Christine Drazan | C12: was 39 | D12: now 41
B13: Moved with the same three fixes above.
B15: Gave to two or more of the six | C15: was 57 | D15: now 53
B16: The earlier 57 never reproduced when we recounted from scratch. 53 is counted directly from the Republican households tab.
B18: Candidate shares | C18: was — | D18: now moved 0–2 points
B19: Zimmerman 49%, Arnold 45%, Torres 42%, Brim-Edwards 42%, Clark 35%, Novick 26%. Progressive councilors: still zero.
B21: Earlier versions you may have seen
B22: An Oct 17 draft showed 340 households with Republican or local-conservative gifts. That was before we added three more Portland conservative committees (Adams, Treece, and the 2022 pro-Gonzalez PAC) and seven Republican caucus and county-party committees on Oct 18, which raised it to 400. Each committee added or left out is on the Committees tab with the reason.
B23: An earlier name-only matcher gave much higher counts (for example, about 45 Republican donors for Torres, where a filing-by-filing check supports 32). It matched people by name anywhere in Oregon. We threw that method out; nothing in this workbook rests on a name alone.

Sheet How to check a row
B2: How to check a row yourself
B4: Every gift in this workbook is written as Filer Id:Transaction ID, for example 24897:5873439. The first number is the committee; the second is the gift.
B6: Look it up in ORESTAR
B7: 1. Go to Oregon's campaign-finance search, ORESTAR (sos.oregon.gov → Elections → ORESTAR → search campaign finance transactions).
B8: 2. Search the committee by its Filer Id, or by name (the Committees tab lists both).
B9: 3. Narrow to the gift's date (the Gifts tab has it), then find the row with that Transaction ID. Exporting the results to Excel shows a Tran Id column.
B10: 4. The filing shows the donor's name, address and employer, the same fields we matched on.
B11: 5. Do the same for the candidate gift on that row. If the two filings share a street address or PO box (with the same ZIP or city), or a ZIP and a specific employer, it's a direct match.
B13: Worked example
B14: Household H012 gave to Olivia Clark, Julia Brim-Edwards. Its Republican gifts are listed as 13998:677176; 13998:761247; 13998:846517; 13998:911093; 15192:1615784; 15192:2145598; 19050:2761997 Look up one candidate gift (e.g. 23199:4778922) and one Republican gift. Both filings show the same address.
B16: Rows marked "Likely"
B17: A few links needed more than one filing: the same employer listed at a home address on one gift and the office on the other, or a third filing that ties two addresses together. Each one says why in the row, and lists the extra Transaction IDs we used. We count them, but we mark them so you can judge for yourself. 7 of the 125 Republican households rest only on links like these.
... B20: Tell us through the contact on whosbuyingpdx.com. Send the household code and the Transaction ID. If we got it wrong, we'll correct it on the Receipts page with the date.

Sheet Words we use
B2: Words we use
B4: Donor
B5: An individual (not a business, PAC or union) who gave a candidate more than $100 since Jan 1, 2023, so their name is on the public filing.
B7: Household
B8: Donors with the same last name at the same home address or PO box: usually a couple. A person who files from two addresses is counted once. Siblings or other relatives who only share a business address are separate households. Codes starting with H gave to Republicans; codes starting with P gave only to Portland conservatives.
B10: Pair
B11: One donor on one candidate's list. A household that gave to three candidates makes three pairs. Candidate percentages use pairs; the site's household totals use households.
B13: Republican campaign
B14: One of 25 committees that filed as Republican: candidates (Drazan, Buehler, Dudley and others), the Oregon Republican Party, county parties, and House and Senate Republican caucus funds. Gifts back to 2006.
B16: Portland conservative
B17: Six local nonpartisan campaigns whose donors overlap the business-backed slate and none of the progressive councilors running against them: Rene Gonzalez, Nathan Vasquez, Vadim Mozyrsky, Sam Adams, Pam Treece, and Portland Accountability PAC (2022, pro-Gonzalez).
B19: Match
... B32: Amounts are rounded to $250 under $1,000, otherwise to $1,000. The exact amount is in the filing.

Sheet Candidates
A1: Counts are donor-and-candidate pairs (Steps 1–3). Share = (Republican + Portland conservative) ÷ donors. Total and Share are formulas.
A2: ← Back to Start here
A4: Candidate | B4: Group | C4: Individual donors (over $100, since 2023) | D4: Gave to Republicans | E4: Portland conservative only | F4: Total | G4: Share
A5: Kellie Torres | B5: business-backed | C5: 219 | D5: 32 | E5: 60 | F5: =D5+E5 | G5: =F5/C5
A6: Steve Novick | B6: business-backed | C6: 334 | D6: 25 | E6: 62 | F6: =D6+E6 | G6: =F6/C6
A7: Olivia Clark | B7: business-backed | C7: 320 | D7: 38 | E7: 73 | F7: =D7+E7 | G7: =F7/C7
A8: Eric Zimmerman | B8: business-backed | C8: 288 | D8: 37 | E8: 104 | F8: =D8+E8 | G8: =F8/C8
A9: Eli Arnold | B9: business-backed | C9: 239 | D9: 37 | E9: 71 | F9: =D9+E9 | G9: =F9/C9
A10: Julia Brim-Edwards | B10: business-backed | C10: 489 | D10: 77 | E10: 130 | F10: =D10+E10 | G10: =F10/C10
A11: Tiffany Koyama Lane | B11: comparison (progressive) | C11: 269 | D11: 0 | E11: 0 | F11: =D11+E11 | G11: =F11/C11
A12: Mitch Green | B12: comparison (progressive) | C12: 227 | D12: 0 | E12: 0 | F12: =D12+E12 | G12: =F12/C12
A13: Angelita Morillo | B13: comparison (progressive) | C13: 203 | D13: 0 | E13: 0 | F13: =D13+E13 | G13: =F13/C13
A14: Shannon Singleton | B14: comparison (progressive) | C14: 172 | D14: 0 | E14: 2 | F14: =D14+E14 | G14: =F14/C14

Sheet Republican households
A1: One row per household that gave to at least one of the six and also to a Republican campaign. Every gift is on the Gifts tab with its date and committee.
A2: ← Back to Start here
A4: Household | B4: Slate candidates given to | C4: No. of slate candidates | D4: Gave to Drazan | E4: Republican campaigns | F4: First Republican gift (year) | G4: Latest Republican gift (year) | H4: No. of Republican gifts | I4: Republican gifts, total ($, rounded) | J4: Match basis | K4: Verification | L4: Why, if not a direct match | M4: Republican gifts (Filer Id:Tran Id) | N4: Slate gifts (Filer Id:Tran Id)
A5: H001 | B5: Steve Novick | C5: 1 | D5: No | E5: Friends of Allen Alley | F5: 2008 | G5: 2009 | H5: 2 | I5: 3000 | J5: Street address or PO box | K5: Confirmed | M5: 12878:307941; 12878:554702 | N5: 15109:5022280
A6: H002 | B6: Julia Brim-Edwards | C6: 1 | D6: Yes | E6: Bud Pierce for a Better Oregon; Citizens to Elect Dennis Richardson; Friends of Allen Alley; Friends of Chris Dudley; Friends of Christine Drazan; Friends of Kim Thatcher; Knute for Governor | F6: 2008 | G6: 2026 | H6: 18 | I6: 51000 | J6: Street address or PO box | K6: Confirmed | M6: 12878:346009; 12878:561926; 13998:737042; 13998:780531; 13998:810187; 13998:867527; 13998:889878; 4155:1691136; 12878:2214008; 12878:2255309; 17397:2338132; 17397:2400409; 15192:2800100; 15192:2903943; 15192:3008676; 4871:3576688; 19050:5753126; 19050:5771083 | N6: 21206:4913049; 21206:4530514
A7: H003 | B7: Olivia Clark, Julia Brim-Edwards | C7: 2 | D7: No | E7: Friends of Allen Alley | F7: 2008 | G7: 2008 | H7: 1 | I7: 250 | J7: Street address or PO box | K7: Confirmed | M7: 12878:373393 | N7: 23199:4712016; 21206:4853079; 21206:4536309
A8: H004 | B8: Julia Brim-Edwards | C8: 1 | D8: No | E8: Friends of Allen Alley | F8: 2008 | G8: 2008 | H8: 2 | I8: 1000 | J8: Street address or PO box | K8: Confirmed | M8: 12878:406431; 12878:436939 | N8: 21206:5627329; 21206:4572188
A9: H005 | B9: Kellie Torres, Olivia Clark, Julia Brim-Edwards | C9: 3 | D9: No | E9: Friends of Allen Alley | F9: 2008 | G9: 2008 | H9: 1 | I9: 500 | J9: Street address or PO box | K9: Confirmed | M9: 12878:449303 | N9: 24897:5846576; 24897:5846642; 23199:5633047; 23199:5085923; 21206:5747271; 21206:4551175
A10: H006 | B10: Julia Brim-Edwards | C10: 1 | D10: No | E10: Bring Balance to Salem PAC; Friends of Allen Alley; Friends of Chris Dudley; Friends of Will Lathrop; Knute Buehler for Secretary of State; Knute for Governor; The Leadership Fund; Working Families for Bruce Starr | F10: 2008 | G10: 2024 | H10: 10 | I10: 62000 | J10: Street address or PO box | K10: Confirmed | M10: 12878:456114; 13998:931177; 2752:1197497; 2690:1221981; 2690:1272145; 15192:1283234; 15192:3012967; 21896:4788154; 21717:5108443; 21896:5124500 | N10: 21206:4860147
A11: H007 | B11: Eric Zimmerman | C11: 1 | D11: No | E11: Friends of Allen Alley | F11: 2008 | G11: 2010 | H11: 3 | I11: 8000 | J11: Street address or PO box | K11: Confirmed | M11: 12878:467460; 12878:615753; 12878:730702 | N11: 17629:5813937
A12: H008 | B12: Kellie Torres, Steve Novick, Eric Zimmerman | C12: 3 | D12: No | E12: Friends of Allen Alley | F12: 2008 | G12: 2008 | H12: 1 | I12: 500 | J12: Hand review | K12: Likely | L12: The two gifts list the same law firm under two versions of its name, one from a home address and one from the office. No single filing ties the two addresses. | M12: 12878:467561 | N12: 24897:5873385; 15109:5863396; 17629:5852827
A13: H009 | B13: Olivia Clark | C13: 1 | D13: No | E13: Dudley for Oregon; Friends of Chris Dudley | F13: 2009 | G13: 2026 | H13: 2 | I13: 6000 | J13: Street address or PO box, ZIP + employer | K13: Confirmed | M13: 13998:645475; 24693:5578379 | N13: 23199:5868497
A14: H010 | B14: Julia Brim-Edwards | C14: 1 | D14: No | E14: Dudley for Oregon; Friends of Chris Dudley | F14: 2009 | G14: 2026 | H14: 2 | I14: 3000 | J14: Street address or PO box | K14: Confirmed | M14: 13998:645691; 24693:5639462 | N14: 21206:5704151
A15: H011 | B15: Eli Arnold | C15: 1 | D15: No | E15: Friends of Chris Dudley | F15: 2009 | G15: 2010 | H15: 2 | I15: 500 | J15: Street address or PO box | K15: Confirmed | M15: 13998:661714; 13998:819738 | N15: 23295:5505111; 23295:5505122
A16: H012 | B16: Olivia Clark, Julia Brim-Edwards | C16: 2 | D16: Yes | E16: Buehler For a United Oregon; Friends of Chris Dudley; Friends of Christine Drazan | F16: 2010 | G16: 2018 | H16: 7 | I16: 1000 | J16: Street address or PO box, ZIP + employer | K16: Confirmed | M16: 13998:677176; 13998:761247; 13998:846517; 13998:911093; 15192:1615784; 15192:2145598; 19050:2761997 | N16: 23199:4778922; 21206:4536329
A17: H013 | B17: Kellie Torres, Eric Zimmerman | C17: 2 | D17: Yes | E17: Friends of Allen Alley; Friends of Chris Dudley; Friends of Christine Drazan; Knute for Governor | F17: 2010 | G17: 2026 | H17: 7 | I17: 37000 | J17: Street address or PO box | K17: Confirmed | M17: 13998:704478; 13998:861561; 12878:2206664; 15192:2729829; 19050:4388949; 19050:5722342; 19050:5838902 | N17: 24897:5873453; 24897:5760928; 17629:5852794
A18: H014 | B18: Julia Brim-Edwards | C18: 1 | D18: No | E18: The Leadership Fund | F18: 2010 | G18: 2010 | H18: 1 | I18: 500 | J18: ZIP + employer | K18: Confirmed | M18: 2690:723588 | N18: 21206:4921375
A19: H015 | B19: Julia Brim-Edwards | C19: 1 | D19: No | E19: The Leadership Fund | F19: 2010 | G19: 2010 | H19: 1 | I19: 250 | J19: Street address or PO box | K19: Confirmed | M19: 2690:726280 | N19: 21206:5857115; 21206:4536341
A20: H016 | B20: Steve Novick, Eli Arnold | C20: 2 | D20: Yes | E20: Friends of Chris Dudley; Friends of Christine Drazan; Friends of Will Lathrop; Knute for Governor | F20: 2010 | G20: 2024 | H20: 14 | I20: 66000 | J20: Street address or PO box, ZIP + employer | K20: Confirmed | M20: 13998:775628; 13998:812221; 13998:817465; 13998:862917; 13998:936530; 15192:2620145; 15192:2620146; 15192:2889599; 15192:2894245; 15192:2948046; 15192:3003198; 15192:3009905; 19050:4375712; 21896:5086898 | N20: 15109:5830453; 15109:5685046; 15109:4785325; 23295:5686494; 23295:5674943
A21: H017 | B21: Kellie Torres, Eric Zimmerman | C21: 2 | D21: No | E21: Friends of Chris Dudley | F21: 2010 | G21: 2010 | H21: 2 | I21: 1000 | J21: Hand review | K21: Likely | L21: The two gifts list the same firm (one abbreviated), one from a home address and one from the office. | M21: 13998:797496; 13998:949704 | N21: 24897:5812169; 17629:5868399
A22: H018 | B22: Kellie Torres | C22: 1 | D22: Yes | E22: Bud Pierce for a Better Oregon; Citizens to Elect Dennis Richardson; Evergreen Oregon PAC; Friends of Allen Alley; Friends of Chris Dudley; Friends of Christine Drazan; Knute Buehler for Secretary of State; Knute for Governor | F22: 2010 | G22: 2026 | H22: 19 | I22: 16000 | J22: Street address or PO box | K22: Confirmed | M22: 13998:949689; 13998:949688; 15192:1270034; 15192:1382465; 15192:1414274; 4155:1764279; 4155:1862480; 12878:2204149; 12878:2227651; 17397:2227560; 17397:2275366; 17397:2402657; 15192:2871059; 20202:3282978; 20202:3824692; 19050:4312835; 19050:5099437; 19050:5672089; 19050:5778485 | N22: 24897:5760945
A23: H019 | B23: Kellie Torres, Steve Novick, Olivia Clark, Eric Zimmerman, Julia Brim-Edwards | C23: 5 | D23: No | E23: Friends of Chris Dudley | F23: 2010 | G23: 2010 | H23: 1 | I23: 1000 | J23: Hand review | K23: Likely | L23: Another filing ties the Republican-gift address to the employer on the candidate gifts. Weakest link in the set: several relatives share that office. Supporting filings (Tran Id): 3510647. | M23: 13998:890502 | N23: 24897:5658420; 21206:5555015; 21206:4913050; 21206:4530526; 15109:5717509; 23199:5473737; 23199:5375105; 17629:5813892; 17629:5017065
A24: H020 | B24: Kellie Torres, Steve Novick, Olivia Clark, Eric Zimmerman, Julia Brim-Edwards | C24: 5 | D24: No | E24: Starr, Bruce, for State Senate Committee | F24: 2010 | G24: 2010 | H24: 1 | I24: 250 | J24: ZIP + employer | K24: Confirmed | M24: 2752:944216 | N24: 24897:5846625; 15109:5717485; 23199:5844223; 23199:4931476; 17629:5813959; 17629:5778160; 21206:4551189
A25: H021 | B25: Kellie Torres, Olivia Clark, Eric Zimmerman, Julia Brim-Edwards | C25: 4 | D25: Yes | E25: Bud Pierce for a Better Oregon; Citizens to Elect Dennis Richardson; Friends of Christine Drazan; Friends of Kim Thatcher; Knute Buehler for Secretary of State; Knute for Governor; The Leadership Fund | F25: 2011 | G25: 2026 | H25: 7 | I25: 5000 | J25: Street address or PO box | K25: Confirmed | M25: 15192:1125657; 4155:1832575; 17397:2294547; 15192:2887948; 2690:3164998; 4871:3474655; 19050:5804309 | N25: 24897:5878236; 23199:5800302; 17629:5813894; 21206:4921372; 21206:4568202
A26: H022 | B26: Kellie Torres, Steve Novick, Eric Zimmerman, Julia Brim-Edwards | C26: 4 | D26: No | E26: Bruce Starr for State Senate Committee; Friends of Will Lathrop; Knute Buehler for Secretary of State; Knute for Governor; Working Families for Bruce Starr | F26: 2012 | G26: 2024 | H26: 7 | I26: 23000 | J26: Street address or PO box | K26: Confirmed | M26: 2752:1155723; 2752:1389544; 15192:1412291; 2752:1799268; 15192:2622425; 15192:3050049; 21896:4770292 | N26: 24897:5831612; 24897:5780400; 15109:5685078; 17629:5679864; 17629:4993392; 21206:5578333; 21206:4568186
A27: H023 | B27: Kellie Torres, Olivia Clark, Eli Arnold, Julia Brim-Edwards | C27: 4 | D27: No | E27: Bud Pierce for a Better Oregon; Citizens to Elect Dennis Richardson; Friends of Will Lathrop; Knute Buehler for Secretary of State; Knute for Governor | F27: 2012 | G27: 2024 | H27: 9 | I27: 4000 | J27: Street address or PO box | K27: Confirmed | M27: 15192:1176724; 15192:1413842; 4155:1793078; 4155:1852194; 17397:2293621; 15192:2733414; 15192:2790090; 21896:4775465; 21896:5086955 | N27: 24897:5761006; 23199:5633082; 23295:5820984; 23295:5704040; 21206:5578345; 21206:4536304
A28: H024 | B28: Steve Novick, Olivia Clark, Julia Brim-Edwards | C28: 3 | D28: No | E28: Buehler For a United Oregon; Knute Buehler for Secretary of State; Knute for Governor | F28: 2012 | G28: 2018 | H28: 6 | I28: 7000 | J28: Street address or PO box | K28: Confirmed | M28: 15192:1223332; 15192:1639297; 15192:1845152; 15192:2599519; 15192:2814827; 15192:3043271 | N28: 15109:5732244; 23199:5868476; 21206:5555061; 21206:4853135; 21206:4563014
A29: H025 | B29: Julia Brim-Edwards | C29: 1 | D29: Yes | E29: Friends of Christine Drazan; Friends of Will Lathrop; Working Families for Bruce Starr | F29: 2012 | G29: 2024 | H29: 11 | I29: 23000 | J29: Street address or PO box | K29: Confirmed | M29: 2752:1254706; 2752:1277399; 2752:1404944; 19050:4145981; 19050:4350989; 19050:4399899; 19050:4399900; 19050:4399901; 19050:4402475; 21896:4861611; 21896:5123890 | N29: 21206:5647917; 21206:5578344; 21206:4572241
A30: H026 | B30: Kellie Torres, Steve Novick, Olivia Clark, Eric Zimmerman, Julia Brim-Edwards | C30: 5 | D30: Yes | E30: Citizens to Elect Dennis Richardson; Friends of Christine Drazan; Hicks for Senate; Knute Buehler for Secretary of State; Knute for Governor; Tim Knopp for State Senate | F30: 2012 | G30: 2025 | H30: 10 | I30: 4000 | J30: Street address or PO box | K30: Confirmed | M30: 15627:1267733; 15192:1412312; 15627:1840306; 15627:2346191; 4155:2350441; 4155:2428898; 15192:2591021; 19050:3033736; 15627:4368289; 24485:5485678 | N30: 24897:5846627; 15109:5793246; 23199:5473715; 23199:5061732; 17629:5651895; 17629:4968603; 21206:5704160; 21206:5647915; 21206:4853174; 21206:4530578
A31: H027 | B31: Eli Arnold | C31: 1 | D31: Yes | E31: Bud Pierce for a Better Oregon; Friends of Christine Drazan; Knute Buehler for Secretary of State; Knute for Governor | F31: 2012 | G31: 2022 | H31: 8 | I31: 1000 | J31: Street address or PO box | K31: Confirmed | M31: 15192:1285976; 17397:2302002; 15192:2716443; 15192:2861417; 15192:2913113; 15192:3041308; 19050:4210576; 19050:4260172 | N31: 23295:4888919
A32: H028 | B32: Julia Brim-Edwards | C32: 1 | D32: No | E32: Citizens to Elect Dennis Richardson; Knute Buehler for Secretary of State; Knute for Governor | F32: 2012 | G32: 2018 | H32: 10 | I32: 6000 | J32: Street address or PO box | K32: Confirmed | M32: 15192:1334390; 4155:2321617; 15192:2621761; 15192:2651802; 15192:2652083; 15192:2672555; 15192:2701925; 15192:2743422; 15192:2784660; 15192:2910692 | N32: 21206:5555087
A33: H029 | B33: Eli Arnold | C33: 1 | D33: Yes | E33: Bud Pierce for a Better Oregon; Friends of Christine Drazan; Friends of Kim Thatcher; Knute Buehler for Secretary of State; Knute for Governor | F33: 2012 | G33: 2026 | H33: 5 | I33: 1000 | J33: Street address or PO box | K33: Confirmed | M33: 15192:1374446; 17397:2365415; 15192:2992803; 4871:3638153; 19050:5795169 | N33: 23295:4967848
A34: H030 | B34: Eli Arnold | C34: 1 | D34: Yes | E34: Citizens to Elect Dennis Richardson; Friends of Christine Drazan; Knute Buehler for Secretary of State; Knute for Governor | F34: 2012 | G34: 2022 | H34: 7 | I34: 37000 | J34: Street address or PO box | K34: Confirmed | M34: 15192:1381781; 15192:1398516; 4155:1798136; 15192:2888905; 15192:2985679; 15192:3012966; 19050:4397781 | N34: 23295:4926094
A35: H031 | B35: Steve Novick, Olivia Clark, Eli Arnold, Julia Brim-Edwards | C35: 4 | D35: No | E35: Friends of Jeff Helfrich | F35: 2012 | G35: 2026 | H35: 2 | I35: 250 | J35: Street address or PO box | K35: Confirmed | M35: 15984:1379009; 15984:5516614 | N35: 15109:5503410; 15109:5080567; 15109:4813722; 23199:5844271; 23199:4907904; 23295:5865555; 21206:5555028; 21206:4853139; 21206:4530557
A36: H032 | B36: Julia Brim-Edwards | C36: 1 | D36: No | E36: Knute Buehler for Secretary of State | F36: 2012 | G36: 2012 | H36: 1 | I36: 500 | J36: ZIP + employer | K36: Confirmed | M36: 15192:1414427 | N36: 21206:5627280
A37: H033 | B37: Kellie Torres, Steve Novick, Olivia Clark, Eric Zimmerman, Eli Arnold, Julia Brim-Edwards | C37: 6 | D37: No | E37: Bruce Starr for State Senate Committee | F37: 2014 | G37: 2014 | H37: 1 | I37: 250 | J37: Hand review | K37: Likely | L37: A chain of other filings ties the candidate-gift address to the employer on the Republican gift. One gift, in 2014. Supporting filings (Tran Id): 2140128, 4076909, 4323067. | M37: 2752:1797354 | N37: 24897:5846650; 15109:5830354; 23199:5844238; 17629:5679849; 23295:5821161; 21206:5497844; 21206:4530484
A38: H034 | B38: Julia Brim-Edwards | C38: 1 | D38: No | E38: Bruce Starr for State Senate Committee | F38: 2014 | G38: 2014 | H38: 1 | I38: 1000 | J38: Street address or PO box | K38: Confirmed | M38: 2752:1856576 | N38: 21206:4574705
A39: H035 | B39: Kellie Torres, Steve Novick, Olivia Clark, Eric Zimmerman, Eli Arnold, Julia Brim-Edwards | C39: 6 | D39: No | E39: Bruce Starr for State Senate Committee | F39: 2014 | G39: 2014 | H39: 1 | I39: 250 | J39: Street address or PO box | K39: Confirmed | M39: 2752:1873970 | N39: 24897:5633829; 15109:5685083; 15109:4725902; 23199:5473723; 17629:5778131; 23295:5850163; 23295:5554616; 21206:5555055; 21206:4551187
A40: H036 | B40: Steve Novick | C40: 1 | D40: No | E40: Citizens to Elect Dennis Richardson | F40: 2014 | G40: 2014 | H40: 1 | I40: 250 | J40: Street address or PO box | K40: Confirmed | M40: 4155:1868276 | N40: 15109:4865093
A41: H037 | B41: Eric Zimmerman, Eli Arnold, Julia Brim-Edwards | C41: 3 | D41: No | E41: Bruce Starr for State Senate Committee; Knute for Governor | F41: 2014 | G41: 2018 | H41: 5 | I41: 8000 | J41: Street address or PO box | K41: Confirmed | M41: 2752:1896834; 15192:2652081; 15192:2784661; 15192:2853284; 15192:3021279 | N41: 17629:5778130; 23295:5704060; 21206:5554984; 21206:4853068; 21206:4530522
...

Sheet PC-only households
A1: One row per household that gave to at least one of the six and to a Portland conservative campaign, but to no Republican campaign we could match. Donor codes link to the Candidate PC matches tab, which has each gift's Transaction ID.
A2: ← Back to Start here
A4: Household | B4: Slate candidates given to | C4: No. of slate candidates | D4: Portland conservative campaigns | E4: Donor codes in this household | F4: No. of donors
A5: P001 | B5: Steve Novick, Olivia Clark, Eric Zimmerman, Eli Arnold, Julia Brim-Edwards | C5: 5 | D5: Friends of Sam Adams; Friends of Vadim; Portland Accountability PAC; Rene For Portland; Rene for Portland | E5: C218 | F5: 1
A6: P002 | B6: Steve Novick, Julia Brim-Edwards | C6: 2 | D6: Friends of Sam Adams | E6: C058 | F6: 1
A7: P003 | B7: Steve Novick | C7: 1 | D7: Friends of Sam Adams | E7: C061 | F7: 1
A8: P004 | B8: Steve Novick, Olivia Clark | C8: 2 | D8: Rene For Portland; Rene for Portland | E8: C079, C172 | F8: 2
A9: P005 | B9: Steve Novick, Olivia Clark, Eric Zimmerman, Eli Arnold | C9: 4 | D9: Vote Vasquez | E9: C308 | F9: 1
A10: P006 | B10: Steve Novick, Julia Brim-Edwards | C10: 2 | D10: Friends of Sam Adams | E10: C048 | F10: 1
A11: P007 | B11: Steve Novick | C11: 1 | D11: Rene For Portland | E11: C089 | F11: 1
A12: P008 | B12: Steve Novick | C12: 1 | D12: Vote Vasquez | E12: C303 | F12: 1
A13: P009 | B13: Steve Novick, Olivia Clark | C13: 2 | D13: Friends of Vadim | E13: C233 | F13: 1
A14: P010 | B14: Steve Novick, Olivia Clark | C14: 2 | D14: Friends of Vadim; Rene For Portland; Rene for Portland | E14: C080 | F14: 1
A15: P011 | B15: Steve Novick | C15: 1 | D15: Friends of Sam Adams | E15: C059 | F15: 1
A16: P012 | B16: Steve Novick, Olivia Clark, Julia Brim-Edwards | C16: 3 | D16: Friends of Sam Adams | E16: C030 | F16: 1
... A269: P265 | B269: Kellie Torres | C269: 1 | D269: Rene For Portland | E269: C141 | F269: 1

Sheet Candidate R matches
A1: One row per donor per candidate. A household that gave to three candidates appears three times; two people in one household who both gave to the same candidate appear twice.
A2: ← Back to Start here
A4: Candidate | B4: Household | C4: Verification | D4: Match basis | E4: Republican campaigns | F4: Latest Republican gift (year) | G4: Republican gifts ($, rounded) | H4: Why, if not a direct match | I4: Candidate gifts (Filer Id:Tran Id) | J4: Republican gifts (Filer Id:Tran Id)
A5: Eli Arnold | B5: H011 | C5: Confirmed | D5: Street address or PO box | E5: Friends of Chris Dudley | F5: 2010 | G5: 500 | I5: 23295:5505111; 23295:5505122 | J5: 13998:661714; 13998:819738
A6: Eli Arnold | B6: H016 | C6: Confirmed | D6: ZIP + employer | E6: Knute for Governor | F6: 2018 | G6: 41000 | I6: 23295:5686494 | J6: 15192:2620145; 15192:2620146; 15192:2889599; 15192:2894245; 15192:2948046; 15192:3003198; 15192:3009905
A7: Eli Arnold | B7: H016 | C7: Confirmed | D7: Street address or PO box | E7: Friends of Christine Drazan; Friends of Will Lathrop | F7: 2024 | G7: 1000 | I7: 23295:5674943 | J7: 19050:4375712; 21896:5086898
A8: Eli Arnold | B8: H023 | C8: Confirmed | D8: Street address or PO box | E8: Citizens to Elect Dennis Richardson | F8: 2014 | G8: 500 | I8: 23295:5820984; 23295:5704040 | J8: 4155:1793078; 4155:1852194
A9: Eli Arnold | B9: H027 | C9: Confirmed | D9: Street address or PO box | E9: Bud Pierce for a Better Oregon; Friends of Christine Drazan; Knute Buehler for Secretary of State; Knute for Governor | F9: 2022 | G9: 1000 | I9: 23295:4888919 | J9: 15192:1285976; 17397:2302002; 15192:2716443; 15192:2861417; 15192:2913113; 15192:3041308; 19050:4210576; 19050:4260172
A10: Eli Arnold | B10: H029 | C10: Confirmed | D10: Street address or PO box | E10: Bud Pierce for a Better Oregon; Friends of Christine Drazan; Friends of Kim Thatcher; Knute Buehler for Secretary of State; Knute for Governor | F10: 2026 | G10: 1000 | I10: 23295:4967848 | J10: 15192:1374446; 17397:2365415; 15192:2992803; 4871:3638153; 19050:5795169
A11: Eli Arnold | B11: H030 | C11: Confirmed | D11: Street address or PO box | E11: Citizens to Elect Dennis Richardson; Friends of Christine Drazan; Knute Buehler for Secretary of State; Knute for Governor | F11: 2022 | G11: 37000 | I11: 23295:4926094 | J11: 15192:1381781; 15192:1398516; 4155:1798136; 15192:2888905; 15192:2985679; 15192:3012966; 19050:4397781
A12: Eli Arnold | B12: H031 | C12: Confirmed | D12: Street address or PO box | E12: Friends of Jeff Helfrich | F12: 2026 | G12: 250 | I12: 23295:5865555 | J12: 15984:1379009; 15984:5516614
A13: Eli Arnold | B13: H033 | C13: Likely | D13: Hand review | E13: Bruce Starr for State Senate Committee | F13: 2014 | G13: 250 | H13: A chain of other filings ties the candidate-gift address to the employer on the Republican gift. One gift, in 2014. | I13: 23295:5821161 | J13: 2752:1797354
A14: Eli Arnold | B14: H035 | C14: Confirmed | D14: Street address or PO box | E14: Bruce Starr for State Senate Committee | F14: 2014 | G14: 250 | I14: 23295:5850163; 23295:5554616 | J14: 2752:1873970
A15: Eli Arnold | B15: H037 | C15: Confirmed | D15: Street address or PO box | E15: Bruce Starr for State Senate Committee; Knute for Governor | F15: 2018 | G15: 8000 | I15: 23295:5704060 | J15: 2752:1896834; 15192:2652081; 15192:2784661; 15192:2853284; 15192:3021279
A16: Eli Arnold | B16: H043 | C16: Confirmed | D16: Street address or PO box | E16: Friends of Will Lathrop | F16: 2024 | G16: 500 | I16: 23295:5820948; 23295:4943195; 23295:4926096 | J16: 21896:5123848
A17: Eli Arnold | B17: H048 | C17: Confirmed | D17: Street address or PO box | E17: Bud Pierce for a Better Oregon | F17: 2016 | G17: 1000 | I17: 23295:4926099 | J17: 17397:2347630
A18: Eli Arnold | B18: H055 | C18: Confirmed | D18: Street address or PO box | E18: Knute for Governor | F18: 2018 | G18: 12000 | I18: 23295:4993300 | J18: 15192:2670230; 15192:2804186; 15192:2880177
A19: Eli Arnold | B19: H063 | C19: Confirmed | D19: Street address or PO box | E19: Friends of Christine Drazan; Friends of Jeff Helfrich; Friends of Will Lathrop; Knute for Governor; Multnomah County Republican Central Committee | F19: 2026 | G19: 10000 | I19: 23295:5459859 | J19: 15192:2832855; 15192:2895015; 15192:2924330; 15192:3018676; 15192:3073436; 19050:4268959; 19050:4389026; 21896:4741334; 21896:5046509; 21896:5123745; 21896:5123947; 21896:5134203; 21896:5134312; 15984:5197923; 15984:5516634; 21594:5548325; 19050:5813334; 19050:5866669
A20: Eli Arnold | B20: H066 | C20: Confirmed | D20: Street address or PO box | E20: Knute for Governor | F20: 2018 | G20: 250 | I20: 23295:5865526; 23295:5820959; 23295:5820960; 23295:5786029; 23295:5747078; 23295:5704091; 23295:5686478; 23295:4967797 | J20: 15192:2906820; 15192:3003976
A21: Eli Arnold | B21: H070 | C21: Confirmed | D21: Street address or PO box | E21: Friends of Christine Drazan; Knute for Governor | F21: 2024 | G21: 4000 | I21: 23295:5098332 | J21: 15192:2958365; 19050:4309117; 19050:4877571
A22: Eli Arnold | B22: H077 | C22: Confirmed | D22: Street address or PO box | E22: Knute for Governor | F22: 2018 | G22: 1000 | I22: 23295:5032662 | J22: 15192:3011754
A23: Eli Arnold | B23: H080 | C23: Confirmed | D23: Street address or PO box | E23: Knute for Governor | F23: 2018 | G23: 250 | I23: 23295:5820930 | J23: 15192:3040524
A24: Eli Arnold | B24: H082 | C24: Confirmed | D24: Street address or PO box | E24: Knute for Governor | F24: 2018 | G24: 3000 | I24: 23295:5032641 | J24: 15192:3053040
A25: Eli Arnold | B25: H084 | C25: Confirmed | D25: Street address or PO box | E25: Knute for Governor | F25: 2018 | G25: 500 | I25: 23295:4808154 | J25: 15192:3068827
... A42: Eric Zimmerman | B42: H007 | C42: Confirmed | D42: Street address or PO box | E42: Friends of Allen Alley | F42: 2010 | G42: 8000 | I42: 17629:5813937 | J42: 12878:467460; 12878:615753; 12878:730702
A43: Eric Zimmerman | B43: H008 | C43: Likely | D43: Hand review | E43: Friends of Allen Alley | F43: 2008 | G43: 500 | H43: The two gifts list the same law firm under two versions of its name, one from a home address and one from the office. No single filing ties the two addresses. Supporting filings (Tran Id): 467561. | I43: 17629:5852827 | J43: 12878:467561
A44: Eric Zimmerman | B44: H013 | C44: Confirmed | D44: Street address or PO box | E44: Friends of Allen Alley; Friends of Chris Dudley; Friends of Christine Drazan; Knute for Governor | F44: 2026 | G44: 37000 | I44: 17629:5852794 | J44: 13998:704478; 13998:861561; 12878:2206664; 15192:2729829; 19050:4388949; 19050:5722342; 19050:5838902
A45: Eric Zimmerman | B45: H017 | C45: Likely | D45: Hand review | E45: Friends of Chris Dudley | F45: 2010 | G45: 1000 | H45: The two gifts list the same firm (one abbreviated), one from a home address and one from the office. Supporting filings (Tran Id): 949704. | I45: 17629:5868399 | J45: 13998:797496; 13998:949704
A46: Eric Zimmerman | B46: H019 | C46: Likely | D46: Hand review | E46: Friends of Chris Dudley | F46: 2010 | G46: 1000 | H46: Another filing ties the Republican-gift address to the employer on the candidate gifts. Weakest link in the set: several relatives share that office. Supporting filings (Tran Id): 3510647, 890502. | I46: 17629:5813892; 17629:5017065 | J46: 13998:890502
A47: Eric Zimmerman | B47: H020 | C47: Likely | D47: Hand review | E47: Starr, Bruce, for State Senate Committee | F47: 2010 | G47: 250 | H47: Same street and ZIP with house numbers one digit apart, and the same distinctive employer under two names. Supporting filings (Tran Id): 3991406, 944216. | I47: 17629:5813959; 17629:5778160 | J47: 2752:944216
A48: Eric Zimmerman | B48: H021 | C48: Confirmed | D48: Street address or PO box | E48: Bud Pierce for a Better Oregon; Citizens to Elect Dennis Richardson; Friends of Christine Drazan; Friends of Kim Thatcher; Knute Buehler for Secretary of State; Knute for Governor; The Leadership Fund | F48: 2026 | G48: 5000 | I48: 17629:5813894 | J48: 15192:1125657; 4155:1832575; 17397:2294547; 15192:2887948; 2690:3164998; 4871:3474655; 19050:5804309
A49: Eric Zimmerman | B49: H022 | C49: Confirmed | D49: Street address or PO box | E49: Bruce Starr for State Senate Committee; Knute Buehler for Secretary of State; Knute for Governor; Working Families for Bruce Starr | F49: 2018 | G49: 22000 | I49: 17629:5679864 | J49: 2752:1155723; 2752:1389544; 15192:1412291; 2752:1799268; 15192:2622425; 15192:3050049
A50: Eric Zimmerman | B50: H022 | C50: Likely | D50: Hand review | E50: Friends of Will Lathrop | F50: 2024 | G50: 500 | H50: The candidate gift lists the employer at a home address; the Republican gift is from that employer's office. Other filings tie both addresses to the same person. Supporting filings (Tran Id): 4770292, 4778133, 5578333. | I50: 17629:4993392 | J50: 21896:4770292
A51: Eric Zimmerman | B51: H026 | C51: Confirmed | D51: Street address or PO box | E51: Tim Knopp for State Senate | F51: 2022 | G51: 2000 | I51: 17629:5651895; 17629:4968603 | J51: 15627:1267733; 15627:1840306; 15627:2346191; 15627:4368289
A52: Eric Zimmerman | B52: H033 | C52: Likely | D52: Hand review | E52: Bruce Starr for State Senate Committee | F52: 2014 | G52: 250 | H52: A chain of other filings ties the candidate-gift address to the employer on the Republican gift. One gift, in 2014. Supporting filings (Tran Id): 1797354, 2140128, 4076909, 4323067. | I52: 17629:5679849 | J52: 2752:1797354
A53: Eric Zimmerman | B53: H035 | C53: Confirmed | D53: Street address or PO box | E53: Bruce Starr for State Senate Committee | F53: 2014 | G53: 250 | I53: 17629:5778131 | J53: 2752:1873970
A54: Eric Zimmerman | B54: H037 | C54: Confirmed | D54: Street address or PO box | E54: Bruce Starr for State Senate Committee; Knute for Governor | F54: 2018 | G54: 8000 | I54: 17629:5778130 | J54: 2752:1896834; 15192:2652081; 15192:2784661; 15192:2853284; 15192:3021279
A55: Eric Zimmerman | B55: H040 | C55: Confirmed | D55: Street address or PO box | E55: Citizens to Elect Dennis Richardson | F55: 2016 | G55: 1000 | I55: 17629:5828875 | J55: 4155:2265543
A56: Eric Zimmerman | B56: H043 | C56: Confirmed | D56: Street address or PO box | E56: Friends of Will Lathrop | F56: 2024 | G56: 500 | I56: 17629:5828801 | J56: 21896:5123848
A57: Eric Zimmerman | B57: H046 | C57: Confirmed | D57: Street address or PO box | E57: Buehler For a United Oregon | F57: 2016 | G57: 250 | I57: 17629:5813942; 17629:5778116; 17629:4993338; 17629:4928139 | J57: 15192:2372574; 15192:2385463; 15192:2439363; 15192:2469214; 15192:2478440
...

Sheet Candidate PC matches
A1: One row per donor per candidate with a Portland conservative match and no Republican match for that candidate. Household codes starting with H also gave to Republicans (for a different candidate's list), so they're counted in the 125, not again here.
A2: ← Back to Start here
A4: Candidate | B4: Household | C4: Donor | D4: Match basis | E4: Portland conservative campaigns | F4: Latest gift (year) | G4: Gifts ($, rounded) | H4: Candidate gifts (Filer Id:Tran Id) | I4: Matched gifts (Filer Id:Tran Id)
A5: Eli Arnold | B5: H101 | C5: C214 | D5: Street address or PO box | E5: Friends of Vadim | F5: 2021 | G5: 250 | H5: 23295:5686443 | I5: 21632:3935244
A6: Eli Arnold | B6: P001 | C6: C218 | D6: Street address or PO box | E6: Friends of Sam Adams; Friends of Vadim; Portland Accountability PAC; Rene For Portland; Rene for Portland | F6: 2024 | G6: 13000 | H6: 23295:5459907 | I6: 21632:3942402; 21605:4312451; 22544:4329715; 21605:4446798; 22544:4577120; 21605:4740724; 21632:4778204; 20340:4797897
A7: Eli Arnold | B7: P005 | C7: C308 | D7: Street address or PO box | E7: Vote Vasquez | F7: 2024 | G7: 500 | H7: 23295:5704079 | I7: 23012:4908855
A8: Eli Arnold | B8: P017 | C8: C235 | D8: Street address or PO box | E8: Friends of Vadim | F8: 2024 | G8: 1000 | H8: 23295:5820906; 23295:4808144 | I8: 21632:4100105; 21632:4778167
A9: Eli Arnold | B9: P023 | C9: C084 | D9: Street address or PO box | E9: Friends of Vadim; Rene For Portland; Rene for Portland | F9: 2024 | G9: 2000 | H9: 23295:5459854 | I9: 21605:3976952; 21605:4179507; 21605:4446929; 21605:4748792; 21632:4778143; 21605:5078067
A10: Eli Arnold | B10: P025 | C10: C193 | D10: Street address or PO box | E10: Friends of Sam Adams; Friends of Vadim; Rene For Portland | F10: 2024 | G10: 2000 | H10: 23295:5786181 | I10: 21632:3881705; 21605:4222565; 21632:4899452; 21632:5050816; 20340:5054050
A11: Eli Arnold | B11: P037 | C11: C271 | D11: Street address or PO box | E11: Portland Accountability PAC | F11: 2023 | G11: 15000 | H11: 23295:5459905 | I11: 22544:4353399; 22544:4562711
A12: Eli Arnold | B12: P051 | C12: C227 | D12: Street address or PO box | E12: Friends of Vadim; Rene For Portland | F12: 2022 | G12: 500 | H12: 23295:5820976 | I12: 21632:4004678; 21605:4222777
A13: Eli Arnold | B13: P053 | C13: C196 | D13: Street address or PO box | E13: Friends of Vadim | F13: 2024 | G13: 500 | H13: 23295:5786133 | I13: 21632:3885689; 21632:4818967; 21632:5050799
A14: Eli Arnold | B14: P057 | C14: C130 | D14: Street address or PO box | E14: Friends of Vadim; Rene For Portland; Rene for Portland; Vote Vasquez | F14: 2024 | G14: 1000 | H14: 23295:4943166 | I14: 21605:4255307; 23012:4619200; 23012:4663848; 21605:4717511; 21632:4778128
A15: Eli Arnold | B15: P066 | C15: C148 | D15: Street address or PO box | E15: Rene For Portland; Rene for Portland | F15: 2024 | G15: 750 | H15: 23295:5786114; 23295:5505130; 23295:4993284 | I15: 21605:4328876; 21605:4446853; 21605:4824151
A16: Eli Arnold | B16: P071 | C16: C153 | D16: Street address or PO box | E16: Rene For Portland | F16: 2022 | G16: 250 | H16: 23295:5850165 | I16: 21605:4343924
... A504: Eric Zimmerman | B504: P133 | C504: C254 | D504: Street address or PO box | E504: Friends of Pam Treece; Friends of Vadim | F504: 2026 | G504: 750 | H504: 17629:5887669 | I504: 21632:4855333; 18397:5625561

Sheet Gifts
A1: Every gift behind the Republican households: each household's gifts to the six candidates and its matched Republican gifts.
A2: ← Back to Start here
A4: Household | B4: Which gift | C4: Committee | D4: Filer Id | E4: Tran Id | F4: Date | G4: Amount ($, rounded) | H4: How it matched
A5: H001 | B5: Gift to a slate candidate | C5: Novick for Portland | D5: 15109 | E5: 5022280 | F5: 2024-09-04 | G5: 250
A6: H001 | B6: Republican gift | C6: Friends of Allen Alley | D6: 12878 | E6: 307941 | F6: 2008-04-30 | G6: 2000 | H6: Street address or PO box
A7: H001 | B7: Republican gift | C7: Friends of Allen Alley | D7: 12878 | E7: 554702 | F7: 2009-04-08 | G7: 1000 | H7: Street address or PO box
A8: H002 | B8: Gift to a slate candidate | C8: Friends of Julia Brim-Edwards | D8: 21206 | E8: 4530514 | F8: 2023-03-14 | G8: 500
A9: H002 | B9: Gift to a slate candidate | C9: Friends of Julia Brim-Edwards | D9: 21206 | E9: 4913049 | F9: 2024-05-14 | G9: 500
A10: H002 | B10: Republican gift | C10: Friends of Allen Alley | D10: 12878 | E10: 346009 | F10: 2008-06-10 | G10: 5000 | H10: Street address or PO box
A11: H002 | B11: Republican gift | C11: Friends of Allen Alley | D11: 12878 | E11: 561926 | F11: 2009-04-23 | G11: 2000 | H11: Street address or PO box
A12: H002 | B12: Republican gift | C12: Friends of Chris Dudley | D12: 13998 | E12: 737042 | F12: 2010-03-29 | G12: 5000 | H12: Street address or PO box
A13: H002 | B13: Republican gift | C13: Friends of Chris Dudley | D13: 13998 | E13: 780531 | F13: 2010-05-05 | G13: 250 | H13: Street address or PO box
A14: H002 | B14: Republican gift | C14: Friends of Chris Dudley | D14: 13998 | E14: 810187 | F14: 2010-06-10 | G14: 5000 | H14: Street address or PO box
A15: H002 | B15: Republican gift | C15: Friends of Chris Dudley | D15: 13998 | E15: 867527 | F15: 2010-08-27 | G15: 500 | H15: Street address or PO box
A16: H002 | B16: Republican gift | C16: Friends of Chris Dudley | D16: 13998 | E16: 889878 | F16: 2010-09-20 | G16: 5000 | H16: Street address or PO box
A17: H002 | B17: Republican gift | C17: Citizens to Elect Dennis Richardson | D17: 4155 | E17: 1691136 | F17: 2014-04-08 | G17: 1000 | H17: Street address or PO box
A18: H002 | B18: Republican gift | C18: Friends of Allen Alley | D18: 12878 | E18: 2214008 | F18: 2016-04-09 | G18: 1000 | H18: Street address or PO box
A19: H002 | B19: Republican gift | C19: Friends of Allen Alley | D19: 12878 | E19: 2255309 | F19: 2016-05-16 | G19: 1000 | H19: Street address or PO box
A20: H002 | B20: Republican gift | C20: Bud Pierce for a Better Oregon | D20: 17397 | E20: 2338132 | F20: 2016-09-06 | G20: 1000 | H20: Street address or PO box
A21: H002 | B21: Republican gift | C21: Bud Pierce for a Better Oregon | D21: 17397 | E21: 2400409 | F21: 2016-10-14 | G21: 1000 | H21: Street address or PO box
... A27: H002 | B27: Republican gift | C27: Friends of Christine Drazan | D27: 19050 | E27: 5771083 | F27: 2026-08-19 | G27: 5000 | H27: Street address or PO box
A28: H003 | B28: Gift to a slate candidate | C28: Friends of Julia Brim-Edwards | D28: 21206 | E28: 4536309 | F28: 2023-03-23 | G28: 500
A29: H003 | B29: Gift to a slate candidate | C29: Friends of Olivia | D29: 23199 | E29: 4712016 | F29: 2023-11-28 | G29: 250
A30: H003 | B30: Gift to a slate candidate | C30: Friends of Julia Brim-Edwards | D30: 21206 | E30: 4853079 | F30: 2024-03-26 | G30: 500
A31: H003 | B31: Republican gift | C31: Friends of Allen Alley | D31: 12878 | E31: 373393 | F31: 2008-08-14 | G31: 250 | H31: Street address or PO box
A32: H004 | B32: Gift to a slate candidate | C32: Friends of Julia Brim-Edwards | D32: 21206 | E32: 4572188 | F32: 2023-05-03 | G32: 250
A33: H004 | B33: Gift to a slate candidate | C33: Friends of Julia Brim-Edwards | D33: 21206 | E33: 5627329 | F33: 2026-04-13 | G33: 500
A34: H004 | B34: Republican gift | C34: Friends of Allen Alley | D34: 12878 | E34: 406431 | F34: 2008-09-10 | G34: 500 | H34: Street address or PO box
A35: H004 | B35: Republican gift | C35: Friends of Allen Alley | D35: 12878 | E35: 436939 | F35: 2008-09-30 | G35: 500 | H35: Street address or PO box
A36: H005 | B36: Gift to a slate candidate | C36: Friends of Julia Brim-Edwards | D36: 21206 | E36: 4551175 | F36: 2023-04-03 | G36: 250
A37: H005 | B37: Gift to a slate candidate | C37: Friends of Olivia | D37: 23199 | E37: 5085923 | F37: 2024-10-06 | G37: 250
A38: H005 | B38: Gift to a slate candidate | C38: Friends of Olivia | D38: 23199 | E38: 5633047 | F38: 2026-03-26 | G38: 250
A39: H005 | B39: Gift to a slate candidate | C39: Friends of Julia Brim-Edwards | D39: 21206 | E39: 5747271 | F39: 2026-07-08 | G39: 250
A40: H005 | B40: Gift to a slate candidate | C40: Kellie Torres for Portland | D40: 24897 | E40: 5846576 | F40: 2026-09-20 | G40: 250
A41: H005 | B41: Gift to a slate candidate | C41: Kellie Torres for Portland | D41: 24897 | E41: 5846642 | F41: 2026-09-20 | G41: 250
A42: H005 | B42: Republican gift | C42: Friends of Allen Alley | D42: 12878 | E42: 449303 | F42: 2008-10-10 | G42: 500 | H42: Street address or PO box
A43: H006 | B43: Gift to a slate candidate | C43: Friends of Julia Brim-Edwards | D43: 21206 | E43: 4860147 | F43: 2024-04-14 | G43: 500
A44: H006 | B44: Republican gift | C44: Friends of Allen Alley | D44: 12878 | E44: 456114 | F44: 2008-10-16 | G44: 2000 | H44: Street address or PO box
A45: H006 | B45: Republican gift | C45: Friends of Chris Dudley | D45: 13998 | E45: 931177 | F45: 2010-10-12 | G45: 20000 | H45: Street address or PO box
A46: H006 | B46: Republican gift | C46: Working Families for Bruce Starr | D46: 2752 | E46: 1197497 | F46: 2012-03-12 | G46: 3000 | H46: Street address or PO box
...

Sheet Committees
A1: Everything we compared donors against, plus committees we considered and left out. Donor columns count pairs; a donor can count under several committees.
A2: ← Back to Start here
A4: Group | B4: Committee | C4: Filer Id | D4: Candidate | E4: Party as filed | F4: Gifts in export from | G4: to | H4: Torres | I4: Novick | J4: Clark | K4: Zimmerman | L4: Arnold | M4: Brim-Edwards | N4: All six | O4: Why included or excluded
A5: Republican | B5: Knute for Governor | C5: 15192 | D5: Knute Buehler | E5: Republican | F5: 2011-08-22 | G5: 2019-09-10 | H5: 16 | I5: 12 | J5: 18 | K5: 19 | L5: 13 | M5: 35 | N5: 113 | O5: Candidate filed as a Republican.
A6: Republican | B6: Friends of Christine Drazan | C6: 19050 | D6: Christine Drazan | E6: Republican | F6: 2018-02-05 | G6: 2026-10-16 | H6: 7 | I6: 3 | J6: 11 | K6: 9 | L6: 15 | M6: 23 | N6: 68 | O6: Candidate filed as a Republican.
A7: Republican | B7: Friends of Will Lathrop | C7: 21896 | D7: Will Lathrop | E7: Republican | F7: 2024-01-02 | G7: 2026-03-31 | H7: 4 | I7: 4 | J7: 1 | K7: 5 | L7: 8 | M7: 8 | N7: 30 | O7: Candidate filed as a Republican.
A8: Republican | B8: Bruce Starr for State Senate Committee | C8: 2752 | D8: Bruce Starr | E8: Republican | F8: 2006-12-18 | G8: 2018-03-31 | H8: 3 | I8: 3 | J8: 4 | K8: 5 | L8: 3 | M8: 7 | N8: 25 | O8: Candidate filed as a Republican.
A9: Republican | B9: Friends of Allen Alley | C9: 12878 | D9: Allen H. Alley | E9: Republican | F9: 2008-03-06 | G9: 2018-02-08 | H9: 5 | I9: 3 | J9: 2 | K9: 3 | L9: 0 | M9: 8 | N9: 21 | O9: Candidate filed as a Republican.
A10: Republican | B10: Citizens to Re-Elect Dennis Richardson | C10: 4155 | D10: Dennis M Richardson | E10: Republican | F10: 2006-12-01 | G10: 2019-02-19 | H10: 3 | I10: 3 | J10: 3 | K10: 2 | L10: 2 | M10: 5 | N10: 18 | O10: Candidate filed as a Republican.
A11: Republican | B11: Friends of Chris Dudley | C11: 13998 | D11: Chris Dudley | E11: Republican | F11: 2009-11-03 | G11: 2011-01-03 | H11: 4 | I11: 2 | J11: 3 | K11: 3 | L11: 1 | M11: 5 | N11: 18 | O11: Candidate filed as a Republican.
A12: Republican | B12: Dudley for Oregon | C12: 24693 | D12: Chris Dudley | E12: Republican | F12: 2026-01-25 | G12: 2026-05-24 | H12: 2 | I12: 1 | J12: 1 | K12: 2 | L12: 1 | M12: 8 | N12: 15 | O12: Candidate filed as a Republican.
A13: Republican | B13: Bud Pierce for a Better Oregon | C13: 17397 | D13: William C Pierce | E13: Republican | F13: 2015-04-26 | G13: 2018-03-01 | H13: 3 | I13: 1 | J13: 2 | K13: 1 | L13: 3 | M13: 3 | N13: 13 | O13: Candidate filed as a Republican.
A14: Republican | B14: Friends of Jeff Helfrich | C14: 15984 | D14: Jeff Helfrich | E14: Republican | F14: 2012-10-06 | G14: 2026-10-12 | H14: 1 | I14: 1 | J14: 3 | K14: 2 | L14: 2 | M14: 3 | N14: 12 | O14: Candidate filed as a Republican.
A15: Republican | B15: Hicks for Senate | C15: 24485 | D15: Brad S Hicks | E15: Republican | F15: 2025-10-16 | G15: 2026-10-16 | H15: 3 | I15: 1 | J15: 2 | K15: 1 | L15: 0 | M15: 3 | N15: 10 | O15: Candidate filed as a Republican.
A16: Republican | B16: Bring Balance to Salem PAC | C16: 21717 | F16: 2024-02-05 | G16: 2026-10-07 | H16: 1 | I16: 2 | J16: 0 | K16: 3 | L16: 0 | M16: 3 | N16: 9 | O16: Republican legislative PAC.
A17: Republican | B17: Friends of Kim Thatcher | C17: 4871 | D17: Kim Thatcher | E17: Republican | F17: 2006-11-27 | G17: 2026-10-12 | H17: 1 | I17: 0 | J17: 2 | K17: 1 | L17: 1 | M17: 3 | N17: 8 | O17: Candidate filed as a Republican.
A18: Republican | B18: The Leadership Fund | C18: 2690 | F18: 2006-11-29 | G18: 2026-10-09 | H18: 1 | I18: 0 | J18: 1 | K18: 1 | L18: 0 | M18: 5 | N18: 8 | O18: House Republican caucus committee (added Oct 18, 2026).
A19: Republican | B19: Courtney Bangs PAC | C19: 20246 | D19: Courtney D Bangs | E19: Republican | F19: 2019-11-22 | G19: 2026-10-11 | H19: 2 | I19: 1 | J19: 2 | K19: 0 | L19: 0 | M19: 1 | N19: 6 | O19: Candidate filed as a Republican.
A20: Republican | B20: Tim Knopp for State Senate | C20: 15627 | D20: Tim Knopp | E20: Republican | F20: 2012-03-07 | G20: 2025-05-22 | H20: 0 | I20: 0 | J20: 2 | K20: 1 | L20: 0 | M20: 1 | N20: 4 | O20: Candidate filed as a Republican.
A21: Republican | B21: Committee to Elect Dennis Linthicum | C21: 17895 | D21: Dennis B Linthicum | E21: Republican | F21: 2016-03-10 | G21: 2026-10-08 | H21: 0 | I21: 0 | J21: 0 | K21: 1 | L21: 1 | M21: 1 | N21: 3 | O21: Candidate filed as a Republican.
A22: Republican | B22: Friends of Anna Scharf | C22: 21575 | D22: Anna Scharf | E22: Republican | F22: 2021-07-15 | G22: 2026-10-15 | H22: 1 | I22: 0 | J22: 1 | K22: 0 | L22: 0 | M22: 1 | N22: 3 | O22: Candidate filed as a Republican.
A23: Republican | B23: Multnomah County Republican Central Committee | C23: 21594 | E23: Republican | F23: 2021-08-04 | G23: 2026-10-05 | H23: 0 | I23: 0 | J23: 0 | K23: 1 | L23: 1 | M23: 0 | N23: 2 | O23: Republican party committee (added Oct 18, 2026).
A24: Republican | B24: Oregon Republican Party | C24: 379 | F24: 2024-02-05 | G24: 2026-10-09 | H24: 0 | I24: 0 | J24: 0 | K24: 0 | L24: 2 | M24: 0 | N24: 2 | O24: State Republican Party.
A25: Republican | B25: Evergreen Oregon PAC | C25: 20202 | F25: 2019-10-27 | G25: 2023-10-02 | H25: 1 | I25: 0 | J25: 0 | K25: 0 | L25: 0 | M25: 0 | N25: 1 | O25: House Republican caucus PAC (added Oct 18, 2026).
A26: Republican | B26: Boquist Leadership Fund | C26: 4893 | D26: Brian J. Boquist | E26: Republican | F26: 2006-11-27 | G26: 2024-11-14 | H26: 0 | I26: 0 | J26: 0 | K26: 0 | L26: 0 | M26: 0 | N26: 0 | O26: Boquist was registered Independent 2021-2023; gifts in those years are not counted as Republican.
A27: Republican | B27: Clackamas County Republican Party | C27: 294 | E27: Republican | F27: 2007-02-01 | G27: 2026-10-09 | H27: 0 | I27: 0 | J27: 0 | K27: 0 | L27: 0 | M27: 0 | N27: 0 | O27: Republican party committee (added Oct 18, 2026).
A28: Republican | B28: Senate Republican Leadership Fund | C28: 20381 | F28: 2020-01-27 | G28: 2020-05-06 | H28: 0 | I28: 0 | J28: 0 | K28: 0 | L28: 0 | M28: 0 | N28: 0 | O28: Senate Republican caucus committee (added Oct 18, 2026).
A29: Republican | B29: Washington County Republican Central Committee | C29: 349 | E29: Republican | F29: 2006-11-27 | G29: 2026-10-05 | H29: 0 | I29: 0 | J29: 0 | K29: 0 | L29: 0 | M29: 0 | N29: 0 | O29: Republican party committee (added Oct 18, 2026).
A30: Portland conservative | B30: Friends of Rene Gonzalez | C30: 21605 | D30: Rene Gonzalez | F30: 2021-08-16 | G30: 2024-12-14 | H30: 48 | I30: 31 | J30: 51 | K30: 71 | L30: 68 | M30: 87 | N30: 356 | O30: Original conservative-leaning nonpartisan race (team judgment). Also meets the overlap rule: none of the progressive councilors' donors match it.
A31: Portland conservative | B31: Friends of Vadim | C31: 21632 | D31: Vadim Mozyrsky | E31: Nonpartisan | F31: 2021-09-08 | G31: 2024-11-28 | H31: 43 | I31: 32 | J31: 44 | K31: 61 | L31: 46 | M31: 91 | N31: 317 | O31: Original conservative-leaning nonpartisan race (team judgment). Also meets the overlap rule: none of the progressive councilors' donors match it.
A32: Portland conservative | B32: Friends of Sam Adams | C32: 20340 | D32: Sam Adams | E32: Nonpartisan | F32: 2020-01-14 | G32: 2026-03-10 | H32: 20 | I32: 36 | J32: 34 | K32: 42 | L32: 18 | M32: 78 | N32: 228 | O32: Passed the overlap test Oct 18, 2026: at least 3% of the slate's donors gave to it and none of the progressive councilors' donors did.
A33: Portland conservative | B33: Vote Vasquez | C33: 23012 | D33: Nathan Vasquez | E33: Nonpartisan | F33: 2023-05-19 | G33: 2026-10-07 | H33: 30 | I33: 19 | J33: 27 | K33: 38 | L33: 41 | M33: 60 | N33: 215 | O33: Original conservative-leaning nonpartisan race (team judgment). Also meets the overlap rule: none of the progressive councilors' donors match it.
A34: Portland conservative | B34: Friends of Pam Treece | C34: 18397 | D34: Pam Treece | E34: Nonpartisan | F34: 2017-05-01 | G34: 2026-10-16 | H34: 12 | I34: 16 | J34: 23 | K34: 21 | L34: 5 | M34: 32 | N34: 109 | O34: Passed the overlap test Oct 18, 2026: at least 3% of the slate's donors gave to it and none of the progressive councilors' donors did.
A35: Portland conservative | B35: Portland Accountability PAC | C35: 22544 | F35: 2022-10-04 | G35: 2023-05-01 | H35: 10 | I35: 13 | J35: 14 | K35: 15 | L35: 6 | M35: 24 | N35: 82 | O35: 2022 PAC backing Rene Gonzalez. Passed the overlap test Oct 18, 2026: at least 3% of the slate's donors gave to it and none of the progressive councilors' donors did.
A36: Excluded | B36: Committee to Elect Loretta Smith | C36: 14377 | D36: Loretta J. Smith | E36: Nonpartisan | F36: 2010-03-12 | G36: 2026-09-25 | O36: Excluded Oct 18, 2026: 3 of Shannon Singleton's donors also gave to her.
A37: Excluded | B37: Dan Ryan for Portland | C37: 20344 | D37: Dan Ryan | E37: Nonpartisan | F37: 2020-01-17 | G37: 2025-10-05 | O37: Excluded Oct 18, 2026: failed the overlap test (3 progressive-councilor donors gave to it).
A38: Excluded | B38: Friends of Mingus Mapps | C38: 20023 | D38: Mingus Mapps | E38: Nonpartisan | F38: 2019-08-31 | G38: 2025-08-22 | O38: Excluded Oct 18, 2026: failed the overlap test (3 progressive-councilor donors gave to it).
A39: Excluded | B39: Friends of Sharon Meieran | C39: 15132 | D39: Sharon E Meieran | E39: Nonpartisan | F39: 2011-07-18 | G39: 2026-10-09 | O39: Excluded Oct 18, 2026: failed the overlap test (3 progressive-councilor donors gave to it).
